Workbook
Name baseretencionuvt: '[1]RETENCIÓN 1'!$K$80
Name basertfte: '[1]RETENCIÓN 2'!$H$154
Name estampilla: [2]calculos!$D$25
Name industria: [2]calculos!$D$24
Name ingresogravable: '[1]RETENCIÓN 1'!$E$37
Name retencioniva: [2]calculos!$C$7
Name retencionrenta: [2]calculos!$G$23
Name tarifaretencion: '[1]RETENCIÓN 1'!$J$80
Name valorcuenta: #REF!
Name valorletras: [2]conversion!$C$17

Sheet Hoja4
AF1: 1 | AG1: enero | AH1: 2019
AF2: 2 | AG2: febrero | AH2: 2020
AF3: 3 | AG3: marzo | AH3: 2021
A4: CERTIFICADO DE SUPERVISIÓN Y AUTORIZACIÓN DE DESEMBOLSO | AF4: 4 | AG4: abril
AF5: 5 | AG5: mayo
AF6: 6 | AG6: junio | AH6: Banco Popular | AI6: Corriente
A7: INFORMACIÓN CONTRACTUAL | AF7: 7 | AG7: julio | AH7: Bancolombia | AI7: Ahorro
A8: Nombre del (la) Contratista | R8: OBJETO | AF8: 8 | AG8: agosto | AH8: BBVA | AI8: Fiducuenta
AF9: 9 | AG9: septiembre | AH9: Banco AV Villas
A10: Tipo de Contrato | H10: PRESTACION DE SERVICIOS | AF10: 10 | AG10: octubre | AH10: Banco de Bogotá
AF11: 11 | AG11: noviembre | AH11: Banco Agrario
A12: Contrato Nº | J12: DE | AF12: 12 | AG12: diciembre | AH12: Bancoomeva
AF13: 13
A14: Documento de Identidad | H14: C.C. | J14: Nº | AF14: 14
AF15: 15
A16: Nombre de Supervisor(a) o Interventor(a) | H16: Diana Andrea Mosquera Garcia | AF16: 16
AF17: 17
A18: Cargo Supervisor(a) o Interventor(a) | H18: Secretaria de Inclusión y Cohesión Social | AF18: 18
A19: MANIFESTACIÓN DE INTENCIÓN | AF19: 19
AF20: 20
A21: Una vez revisada la documentación enviada por el señor | S21: en su calidad de contratista/convenido del Municipio de Quibdó | AF21: 21
A22: de acuerdo con el contrato (convenio) No | F22: =H12 -> 0 | J22: en cumplimiento de la cláusula | N22: 6 | R22: del convenio/contrato en mención, solicito respetuosamente realizar | AF22: 22
A23: el trámite de pago (o desembolso), con base en la siguiente información y anexos de cumplimiento que se relacionan: | AF23: 23
AF24: 24
A25: INFORMACIÓN FINANCIERA | AF25: 25
A26: Número cuenta del (a) Contratista | O26: Banco | Q26: Bancolombia | X26: Tipo cuenta | Z26: Ahorro | AF26: 26
AF27: 27
A28: Fecha de inicio (Según Acta) | Q28: Plazo de Ejecución | U28: 6 | W28: meses, y | Y28: 0 | Z28: días | AF28: 28
S29: , | AF29: 29
A30: Fecha de terminación (Incluye prórrogas) | AF30: 30
AF31: 31
A32: VALOR INICIAL | L32: Prórrogas | P32: Días
A33: Adición 1 | E33: 0 | L33: Prórroga 1
A34: Adición 2 | E34: 0 | L34: Prórroga 2
A35: Adición 3 | L35: Prórroga 3
A36: VALOR TOTAL | E36: =SUM(E32:H35) -> 0
A38: INFORMACIÓN PRESUPUESTAL
S39: ,
C40: No. Certificado Disponibilidad Presupuestal | H40: No. Registro Presupuestal | L40: Fecha Registro Presupuestal | Q40: Código Rubro Presupuestal | X40: Valor a pagar por Rubro Presupuestal en el presente pago
A46: INFORMACIÓN DE APORTES A SEGURIDAD SOCIAL
...

Sheet Hoja1

Sheet CERTIFICADO PARA PAGO
AG1: 1 | AH1: enero | AI1: 2019
A2: MUNICIPIO DE QUIBDO | AG2: 2 | AH2: febrero | AI2: 2020
A3: SEGUIMIENTO A LA EJECUCIÓN CONTRACTUAL
B4: CERTIFICADO DE SUPERVISIÓN Y AUTORIZACIÓN DE DESEMBOLSO | AG4: 3 | AH4: marzo | AI4: 2021
AG5: 4 | AH5: abril
AG6: 5 | AH6: mayo | AI6: Banco Popular | AJ6: Corriente
B7: INFORMACIÓN CONTRACTUAL | AG7: 6 | AH7: junio | AI7: Bancolombia | AJ7: Ahorro
B8: Nombre del (la) Contratista | I8: LEIDY SAMIRA DIAZ MARTINEZ | S8: OBJETO | AG8: 7 | AH8: julio | AI8: BBVA | AJ8: Fiducuenta
AG9: 8 | AH9: agosto | AI9: Banco AV Villas
B10: Tipo de Contrato | I10: PRESTACION DE SERVICIOS | AG10: 9 | AH10: septiembre | AI10: Banco de Bogotá
AG11: 10 | AH11: octubre | AI11: Banco Agrario
B12: Contrato Nº | K12: DE | AG12: 11 | AH12: noviembre | AI12: Bancoomeva
AG13: 12 | AH13: diciembre
B14: Documento de Identidad | I14: C.C. | K14: Nº | L14: 1077444943 | AG14: 13
AG15: 14
B16: Nombre de Supervisor(a) o Interventor(a) | I16: JORGE TADEO LOZANO RUEDA | AG16: 15
AG17: 16
B18: Cargo Supervisor(a) o Interventor(a) | I18: SECRETARIO GENERAL | AG18: 17
B19: MANIFESTACIÓN DE INTENCIÓN | AG19: 18
AG20: 19
B21: Una vez revisada la documentación enviada por el señor | K21: =I8 -> LEIDY SAMIRA DIAZ MARTINEZ | T21: en su calidad de contratista/convenido del Municipio de Quibdó | AG21: 20
B22: de acuerdo con el contrato (convenio) No | G22: =I12 -> 0 | K22: en cumplimiento de la cláusula | S22: del convenio/contrato en mención, solicito respetuosamente realizar | AG22: 21
B23: el trámite de pago (o desembolso), con base en la siguiente información y anexos de cumplimiento que se relacionan: | AG23: 22
AG24: 23
B25: INFORMACIÓN FINANCIERA | AG25: 24
B26: Número cuenta del (a) Contratista | G26: 230-380-19171-8 | P26: Banco | R26: Banco Popular | Y26: Tipo cuenta | AA26: Ahorro | AG26: 25
AG27: 26
B28: Fecha de inicio (Según Acta) | J28: 43864 | R28: Plazo de Ejecución | V28: 4 | X28: meses, y | Z28: 28 | AA28: días | AG28: 27
T29: , | AG29: 28
B30: Fecha de terminación (Incluye prórrogas) | J30: 44012 | AG30: 29
AG31: 30
B32: VALOR DEL CONTRATO | F32: 12538409 | M32: Prórrogas | Q32: Días | AG32: 31
B33: Adición 1 | F33: 0 | M33: Prórroga 1
B34: Adición 2 | F34: 0 | M34: Prórroga 2
B35: Adición 3 | M35: Prórroga 3
B36: Valor total del contrato | F36: =SUM(F32:I35) -> 12538409
B38: INFORMACIÓN PRESUPUESTAL
T39: ,
D40: No. Certificado Disponibilidad Presupuestal | I40: No. Registro Presupuestal | M40: Fecha Registro Presupuestal | R40: Código Rubro Presupuestal | Y40: Valor a pagar por Rubro Presupuestal en el presente pago
Y41: 2302965
...

Sheet pabril
A3: MUNICIPIO DE QUIBDO
B4: CERTIFICADO DE SUPERVISIÓN
B7: INFORMACIÓN CONTRACTUAL
B9: Nombre del (la) Contratista | I9: SEGURIDAD NÁPOLES | S9: OBJETO | U9: LA PRESTACIÓN DEL SERVICIO DE VIGILANCIA Y SEGURIDAD PRIVADA CON ARMA PARA LAS 16 INSTITUCIONES EDUCATIVA (SEDE PREINCIPAL), 2 SEDES EDUCATIAS DEL MUNICIPIO DE QUIBDÓ, LA SEDE ADMINISTRATIVA DE LA SECRETARÍA DE EDUCACIÓN, LA ADMINISTRACIÓN CENTRAL Y LAS DIFERENTES SEDES Y ÁREAS DE LA ALCALDÍA MUNICPAL DE QUIBDÓ.
B11: Tipo de Contrato | I11: INTERVENTORIA
B13: Contrato Nº | I13: 89 | K13: DE | O13: 2016
B15: Documento de Identidad | I15: C.C. | K15: Nº | L15: 860523408-6
B17: Nombre de Supervisor(a) o Interventor(a) | I17: DAICY MARIELA MOSQUERA - HAROLD RAMIREZ OROZCO
B19: Cargo Supervisor(a) o Interventor(a) | I19: SUPERVISORES
B21: INFORMACIÓN FINANCIERA
B23: Número cuenta del (a) Contratista | G23: 17391176580 | P23: Banco | R23: Bancolombia | Y23: Tipo cuenta | AA23: Corriente
B25: Fecha de inicio (Según Acta) | J25: 1 DE ABRIL DE 2016 | R25: Plazo de Ejecución | V25: 9 | X25: meses, y | AA25: días
T26: ,
B27: Fecha de terminación (Incluye prórrogas) | J27: 31 DE DICIEMBRE DE 2016
B29: APORTE ALCALDIA | F29: 1098832907 | M29: Prórrogas | Q29: Días
B30: ADICION 1 | F30: 0 | M30: Prórroga 1
B31: Adición 2 | M31: Prórroga 2
B32: Adición 3 | M32: Prórroga 3
B33: Valor total del contrato | F33: =+F29+F30 -> 1098832907
B35: INFORMACIÓN PRESUPUESTAL
T36: ,
D37: No. Certificado Disponibilidad Presupuestal | I37: No. Registro Presupuestal | M37: Fecha Registro Presupuestal | R37: Código Rubro Presupuestal | Y37: Valor a pagar por Rubro Presupuestal en el presente pago
D38: 42 | I38: 384 | M38: 42460 | R38: 1.1.2.2.2.1.3.2.1 | Y38: =abril!H2+abril!H3 -> 53335349
D39: 42 | I39: 384 | M39: 42460 | R39: 1.2.1.3.2.2.4.2.4 | Y39: =abril!H4+abril!H5 -> 61010135
D40: 42 | I40: 384 | M40: 42460 | R40: 1.2.1.3.2.3.2.2.06 | Y40: =abril!H6 -> 7747061.1
B44: INFORMACIÓN DE APORTES A SEGURIDAD SOCIAL
E46: Salud | L46: EPS | O46: NUEVA EPS | T46: Número de planilla | X46: 1004582912
E48: Pension | L48: Fondo Pensiones | O48: PORVENIR | T48: Número de planilla | X48: 1004582912
E50: A.R.P | L50: A.R.P | O50: POSITIVA | T50: Número de planilla | X50: 1004582912
B51: ***Nota: El pago del Fondo de Solidaridad Pensional - FSP, aplica únicamente cuando la base de cotizacion es mayor a 4 SMMLV.
B53: INFORMACIÓN PARA LA LIQUIDACIÓN DEL PAGO
C55: No. PAGO | E55: PERÍODO DE PAGO | K55: PORCENTAJE DE EJECUCIÓN | N55: VALOR PAGADO | Q55: VALOR A PAGAR SIN IVA | T55: IVA | W55: VALOR TOTAL A PAGAR | AA55: SALDO POR PAGAR
E56: DESDE | H56: HASTA
C57: 1 | E57: 42461 | H57: 42490 | K57: 0.11 | N57: 0 | Q57: 120169825 | T57: 1922720 | W57: =+Q57+T57 -> 122092545 | AA57: =F33-N57-W57 -> 976740362
C60: SE CANCELA FACTURA DE VENTA 280 DE 2016
B64: CERTIFICACIÓN
B66: El / la suscrito (a) supervisor (a) / interventor (a) certifica:
B67: Que, | C67: =+I9 -> SEGURIDAD NÁPOLES | L67: , identificado(a) con | O67: =+I15 -> C.C. | Q67: Nº | R67: =+L15 -> 860523408-6 | W67: cumplió a satisfacción con el objeto del (la)
B68: =+I11 -> INTERVENTORIA | M68: Nº | N68: =+I13 -> 89 | P68: de | Q68: =+O13 -> 2016 | S68: , de acuerdo con el informe presentado.
B70: Que se verificaron los pagos efectuados por el (la) contratista al Sistema General de Seguridad Social y/o aportes parafiscales, correspondiente al presente periodo de pago, los cuales se efectuaron de acuerdo con lo establecido en la Ley 789/2002 y Decreto 1703/2002, y demás Decretos Reglamentarios.
...

Sheet abril
D1: porcentaje | E1: iva proporcional
A2: 26695696 | B2: sede administrativa | D2: =A2/A7 -> 0.22214975 | E2: =D2*A8 -> 427131.76 | H2: =A2+E2 -> 27122828
A3: 25799725 | B3: sede administratica | D3: =A3/A7 -> 0.21469387 | E3: =A8*D3 -> 412796.2 | H3: =A3+E3 -> 26212521
A4: 53375420 | B4: instituciones educativas | D4: =A4/A7 -> 0.44416658 | E4: =A8*D4 -> 854007.96 | H4: =A4+E4 -> 54229428
A5: 6673924 | B5: instituciones educativas | D5: =A5/A7 -> 0.055537436 | E5: =A8*D5 -> 106782.94 | H5: =A5+E5 -> 6780706.9
A6: 7625060 | B6: sedes educativas | D6: =A6/A7 -> 0.063452368 | E6: =A8*D6 -> 122001.14 | H6: =A6+E6 -> 7747061.1
A7: =SUM(A2:A6) -> 120169825 | B7: subtotal | D7: =SUM(D2:D6) -> 1 | E7: =SUM(E2:E6) -> 1922720
A8: 1922720 | B8: iva
A9: =A7+A8 -> 122092545 | B9: total

Sheet pmayo
A3: MUNICIPIO DE QUIBDO
B4: CERTIFICADO DE SUPERVISIÓN
B7: INFORMACIÓN CONTRACTUAL
B9: Nombre del (la) Contratista | I9: SEGURIDAD NÁPOLES | S9: OBJETO | U9: LA PRESTACIÓN DEL SERVICIO DE VIGILANCIA Y SEGURIDAD PRIVADA CON ARMA PARA LAS 16 INSTITUCIONES EDUCATIVA (SEDE PREINCIPAL), 2 SEDES EDUCATIAS DEL MUNICIPIO DE QUIBDÓ, LA SEDE ADMINISTRATIVA DE LA SECRETARÍA DE EDUCACIÓN, LA ADMINISTRACIÓN CENTRAL Y LAS DIFERENTES SEDES Y ÁREAS DE LA ALCALDÍA MUNICPAL DE QUIBDÓ.
B11: Tipo de Contrato | I11: INTERVENTORIA
B13: Contrato Nº | I13: 89 | K13: DE | O13: 2016
B15: Documento de Identidad | I15: C.C. | K15: Nº | L15: 860523408-6
B17: Nombre de Supervisor(a) o Interventor(a) | I17: DAICY MARIELA MOSQUERA - HAROLD RAMIREZ OROZCO
B19: Cargo Supervisor(a) o Interventor(a) | I19: SUPERVISORES
B21: INFORMACIÓN FINANCIERA
B23: Número cuenta del (a) Contratista | G23: 17391176580 | P23: Banco | R23: Bancolombia | Y23: Tipo cuenta | AA23: Corriente
B25: Fecha de inicio (Según Acta) | J25: 1 DE ABRIL DE 2016 | R25: Plazo de Ejecución | V25: 9 | X25: meses, y | AA25: días
T26: ,
B27: Fecha de terminación (Incluye prórrogas) | J27: 31 DE DICIEMBRE DE 2016
B29: APORTE ALCALDIA | F29: 1098832907 | M29: Prórrogas | Q29: Días
B30: ADICION 1 | F30: 0 | M30: Prórroga 1
B31: Adición 2 | M31: Prórroga 2
B32: Adición 3 | M32: Prórroga 3
B33: Valor total del contrato | F33: =+F29+F30 -> 1098832907
B35: INFORMACIÓN PRESUPUESTAL
T36: ,
D37: No. Certificado Disponibilidad Presupuestal | I37: No. Registro Presupuestal | M37: Fecha Registro Presupuestal | R37: Código Rubro Presupuestal | Y37: Valor a pagar por Rubro Presupuestal en el presente pago
D38: 42 | I38: 384 | M38: 42460 | R38: 1.1.2.2.2.1.3.2.1 | Y38: =abril!H2+abril!H3 -> 53335349
D39: 42 | I39: 384 | M39: 42460 | R39: 1.2.1.3.2.2.4.2.4 | Y39: =abril!H4+abril!H5 -> 61010135
D40: 42 | I40: 384 | M40: 42460 | R40: 1.2.1.3.2.3.2.2.06 | Y40: =abril!H6 -> 7747061.1
B44: INFORMACIÓN DE APORTES A SEGURIDAD SOCIAL
E46: Salud | L46: EPS | O46: NUEVA EPS | T46: Número de planilla | X46: 1004582912
E48: Pension | L48: Fondo Pensiones | O48: PORVENIR | T48: Número de planilla | X48: 1004582912
E50: A.R.P | L50: A.R.P | O50: POSITIVA | T50: Número de planilla | X50: 1004582912
B51: ***Nota: El pago del Fondo de Solidaridad Pensional - FSP, aplica únicamente cuando la base de cotizacion es mayor a 4 SMMLV.
B53: INFORMACIÓN PARA LA LIQUIDACIÓN DEL PAGO
C55: No. PAGO | E55: PERÍODO DE PAGO | K55: PORCENTAJE DE EJECUCIÓN | N55: VALOR PAGADO | Q55: VALOR A PAGAR SIN IVA | T55: IVA | W55: VALOR TOTAL A PAGAR | AA55: SALDO POR PAGAR
E56: DESDE | H56: HASTA
C57: 1 | E57: 42491 | H57: 42521 | K57: 0.2222 | N57: =Y38+Y39+Y40 -> 122092545 | Q57: 120169825 | T57: 1922720 | W57: =+Q57+T57 -> 122092545 | AA57: =F33-N57-W57 -> 854647817
C60: SE CANCELA FACTURA DE VENTA 286 DE 2016
B64: CERTIFICACIÓN
B66: El / la suscrito (a) supervisor (a) / interventor (a) certifica:
B67: Que, | C67: =+I9 -> SEGURIDAD NÁPOLES | L67: , identificado(a) con | O67: =+I15 -> C.C. | Q67: Nº | R67: =+L15 -> 860523408-6 | W67: cumplió a satisfacción con el objeto del (la)
B68: =+I11 -> INTERVENTORIA | M68: Nº | N68: =+I13 -> 89 | P68: de | Q68: =+O13 -> 2016 | S68: , de acuerdo con el informe presentado.
B70: Que se verificaron los pagos efectuados por el (la) contratista al Sistema General de Seguridad Social y/o aportes parafiscales, correspondiente al presente periodo de pago, los cuales se efectuaron de acuerdo con lo establecido en la Ley 789/2002 y Decreto 1703/2002, y demás Decretos Reglamentarios.
...

Sheet mayo
D1: porcentaje | E1: iva proporcional
A2: 26695696 | B2: sede administrativa | D2: =A2/A7 -> 0.22214975 | E2: =D2*A8 -> 427131.76
A3: 25799725 | B3: sede administratica | D3: =A3/A7 -> 0.21469387 | E3: =A8*D3 -> 412796.2
A4: 53375420 | B4: instituciones educativas | D4: =A4/A7 -> 0.44416658 | E4: =A8*D4 -> 854007.96
A5: 6673924 | B5: instituciones educativas | D5: =A5/A7 -> 0.055537436 | E5: =A8*D5 -> 106782.94
A6: 7625060 | B6: sedes educativas | D6: =A6/A7 -> 0.063452368 | E6: =A8*D6 -> 122001.14
A7: =SUM(A2:A6) -> 120169825 | B7: subtotal | D7: =SUM(D2:D6) -> 1 | E7: =SUM(E2:E6) -> 1922720
A8: 1922720 | B8: iva
A9: =A7+A8 -> 122092545 | B9: total
E14: =G14/G18 -> 0.44416658 | G14: =3812530*14 -> 53375420 | H14: instituciones educativas
E15: =G15/G18 -> 0.063452368 | G15: =3812530*2 -> 7625060 | H15: sedes educativas
E16: =G16/G18 -> 0.27768718 | G16: =6673924*5 -> 33369620 | H16: administración central
E17: =G17/G18 -> 0.21469387 | G17: =3685675*7 -> 25799725 | H17: sede administración central
E18: -- | G18: =SUM(G14:G17) -> 120169825

Sheet junio
A3: MUNICIPIO DE QUIBDO
B4: CERTIFICADO DE SUPERVISIÓN
B7: INFORMACIÓN CONTRACTUAL
B9: Nombre del (la) Contratista | I9: SEGURIDAD NÁPOLES | S9: OBJETO | U9: LA PRESTACIÓN DEL SERVICIO DE VIGILANCIA Y SEGURIDAD PRIVADA CON ARMA PARA LAS 16 INSTITUCIONES EDUCATIVA (SEDE PREINCIPAL), 2 SEDES EDUCATIAS DEL MUNICIPIO DE QUIBDÓ, LA SEDE ADMINISTRATIVA DE LA SECRETARÍA DE EDUCACIÓN, LA ADMINISTRACIÓN CENTRAL Y LAS DIFERENTES SEDES Y ÁREAS DE LA ALCALDÍA MUNICPAL DE QUIBDÓ.
B11: Tipo de Contrato | I11: PRESTACIÓN DE SERVICIOS
B13: Contrato Nº | I13: 89 | K13: DE | O13: 2016
B15: Documento de Identidad | I15: C.C. | K15: Nº | L15: 860523408-6
B17: Nombre de Supervisor(a) o Interventor(a) | I17: DAICY MARIELA MOSQUERA - HAROLD RAMIREZ OROZCO
B19: Cargo Supervisor(a) o Interventor(a) | I19: SUPERVISORES
B21: INFORMACIÓN FINANCIERA
B23: Número cuenta del (a) Contratista | G23: 17391176580 | P23: Banco | R23: Bancolombia | Y23: Tipo cuenta | AA23: Corriente
B25: Fecha de inicio (Según Acta) | J25: 1 DE ABRIL DE 2016 | R25: Plazo de Ejecución | V25: 9 | X25: meses, y | AA25: días
T26: ,
B27: Fecha de terminación (Incluye prórrogas) | J27: 31 DE DICIEMBRE DE 2016
B29: APORTE ALCALDIA | F29: 1098832907 | M29: Prórrogas | Q29: Días
B30: ADICION 1 | F30: 0 | M30: Prórroga 1
B31: Adición 2 | M31: Prórroga 2
B32: Adición 3 | M32: Prórroga 3
B33: Valor total del contrato | F33: =+F29+F30 -> 1098832907
B35: INFORMACIÓN PRESUPUESTAL
T36: ,
D37: No. Certificado Disponibilidad Presupuestal | I37: No. Registro Presupuestal | M37: Fecha Registro Presupuestal | R37: Código Rubro Presupuestal | Y37: Valor a pagar por Rubro Presupuestal en el presente pago
D38: 42 | I38: 384 | M38: 42460 | R38: 1.1.2.2.2.1.3.2.1 | Y38: =abril!H2+abril!H3 -> 53335349 | AH38: =Y38*9 -> 4.8001814e+08 | AI38: 488264948
D39: 42 | I39: 384 | M39: 42460 | R39: 1.2.1.3.2.2.4.2.4 | Y39: =abril!H4+abril!H5 -> 61010135 | AH39: =Y39*9 -> 5.4909121e+08 | AI39: 548493111
D40: 42 | I40: 384 | M40: 42460 | R40: 1.2.1.3.2.3.2.2.06 | Y40: =abril!H6 -> 7747061.1 | AH40: =Y40*9 -> 69723550 | AI40: 62074812
AH41: =SUM(AH38:AH40) -> 1098832905 | AI41: =SUM(AI38:AI40) -> 1098832871
B44: INFORMACIÓN DE APORTES A SEGURIDAD SOCIAL
E46: Salud | L46: EPS | O46: NUEVA EPS | T46: Número de planilla | X46: 1004582912
E48: Pension | L48: Fondo Pensiones | O48: PORVENIR | T48: Número de planilla | X48: 1004582912
E50: A.R.P | L50: A.R.P | O50: POSITIVA | T50: Número de planilla | X50: 1004582912
B51: ***Nota: El pago del Fondo de Solidaridad Pensional - FSP, aplica únicamente cuando la base de cotizacion es mayor a 4 SMMLV.
B53: INFORMACIÓN PARA LA LIQUIDACIÓN DEL PAGO
C55: No. PAGO | E55: PERÍODO DE PAGO | K55: PORCENTAJE DE EJECUCIÓN | N55: VALOR PAGADO | Q55: VALOR A PAGAR SIN IVA | T55: IVA | W55: VALOR TOTAL A PAGAR | AA55: SALDO POR PAGAR
E56: DESDE | H56: HASTA
C57: 1 | E57: 42522 | H57: 42551 | K57: =pabril!K57*3 -> 0.33 | N57: =pabril!W57+pmayo!W57 -> 244185090 | Q57: 120169825 | T57: 1922720 | W57: =+Q57+T57 -> 122092545 | AA57: =F33-N57-W57 -> 732555272
C60: SE CANCELA FACTURA DE VENTA 305 DE 2016
B64: CERTIFICACIÓN
B66: El / la suscrito (a) supervisor (a) / interventor (a) certifica:
B67: Que, | C67: =+I9 -> SEGURIDAD NÁPOLES | L67: , identificado(a) con | O67: =+I15 -> C.C. | Q67: Nº | R67: =+L15 -> 860523408-6 | W67: cumplió a satisfacción con el objeto del (la)
B68: =+I11 -> PRESTACIÓN DE SERVICIOS | M68: Nº | N68: =+I13 -> 89 | P68: de | Q68: =+O13 -> 2016 | S68: , de acuerdo con el informe presentado.
...

Sheet julio
A3: MUNICIPIO DE QUIBDO
B4: CERTIFICADO DE SUPERVISIÓN
B7: INFORMACIÓN CONTRACTUAL
B9: Nombre del (la) Contratista | I9: SEGURIDAD NÁPOLES | S9: OBJETO | U9: LA PRESTACIÓN DEL SERVICIO DE VIGILANCIA Y SEGURIDAD PRIVADA CON ARMA PARA LAS 16 INSTITUCIONES EDUCATIVA (SEDE PREINCIPAL), 2 SEDES EDUCATIAS DEL MUNICIPIO DE QUIBDÓ, LA SEDE ADMINISTRATIVA DE LA SECRETARÍA DE EDUCACIÓN, LA ADMINISTRACIÓN CENTRAL Y LAS DIFERENTES SEDES Y ÁREAS DE LA ALCALDÍA MUNICPAL DE QUIBDÓ.
B11: Tipo de Contrato | I11: PRESTACIÓN DE SERVICIOS
B13: Contrato Nº | I13: 89 | K13: DE | O13: 2016
B15: Documento de Identidad | I15: C.C. | K15: Nº | L15: 860523408-6
B17: Nombre de Supervisor(a) o Interventor(a) | I17: DAICY MARIELA MOSQUERA - HAROLD RAMIREZ OROZCO
B19: Cargo Supervisor(a) o Interventor(a) | I19: SUPERVISORES
B21: INFORMACIÓN FINANCIERA
B23: Número cuenta del (a) Contratista | G23: 17391176580 | P23: Banco | R23: Bancolombia | Y23: Tipo cuenta | AA23: Corriente
B25: Fecha de inicio (Según Acta) | J25: 1 DE ABRIL DE 2016 | R25: Plazo de Ejecución | V25: 9 | X25: meses, y | AA25: días
T26: ,
B27: Fecha de terminación (Incluye prórrogas) | J27: 31 DE DICIEMBRE DE 2016
B29: APORTE ALCALDIA | F29: 1098832907 | M29: Prórrogas | Q29: Días
B30: ADICION 1 | F30: 0 | M30: Prórroga 1
B31: Adición 2 | M31: Prórroga 2
B32: Adición 3 | M32: Prórroga 3
B33: Valor total del contrato | F33: =+F29+F30 -> 1098832907
B35: INFORMACIÓN PRESUPUESTAL
T36: ,
D37: No. Certificado Disponibilidad Presupuestal | I37: No. Registro Presupuestal | M37: Fecha Registro Presupuestal | R37: Código Rubro Presupuestal | Y37: Valor a pagar por Rubro Presupuestal en el presente pago
D38: 42 | I38: 384 | M38: 42460 | R38: 1.1.2.2.2.1.3.2.1 | Y38: =abril!H2+abril!H3 -> 53335349 | AH38: =Y38*9 -> 4.8001814e+08 | AI38: 488264948
D39: 42 | I39: 384 | M39: 42460 | R39: 1.2.1.3.2.2.4.2.4 | Y39: =abril!H4+abril!H5 -> 61010135 | AH39: =Y39*9 -> 5.4909121e+08 | AI39: 548493111
D40: 42 | I40: 384 | M40: 42460 | R40: 1.2.1.3.2.3.2.2.06 | Y40: =abril!H6 -> 7747061.1 | AH40: =Y40*9 -> 69723550 | AI40: 62074812
AH41: =SUM(AH38:AH40) -> 1098832905 | AI41: =SUM(AI38:AI40) -> 1098832871
B44: INFORMACIÓN DE APORTES A SEGURIDAD SOCIAL
E46: Salud | G46: 1614100 | L46: EPS | O46: NUEVA EPS | T46: Número de planilla | X46: 8455875396
E48: Pension | G48: 6497440 | L48: Fondo Pensiones | O48: PORVENIR | T48: Número de planilla | X48: 8455875396
E50: A.R.P | G50: 1755200 | L50: A.R.P | O50: POSITIVA | T50: Número de planilla | X50: 8455875396
B51: ***Nota: El pago del Fondo de Solidaridad Pensional - FSP, aplica únicamente cuando la base de cotizacion es mayor a 4 SMMLV.
B53: INFORMACIÓN PARA LA LIQUIDACIÓN DEL PAGO
C55: No. PAGO | E55: PERÍODO DE PAGO | K55: PORCENTAJE DE EJECUCIÓN | N55: VALOR PAGADO | Q55: VALOR A PAGAR SIN IVA | T55: IVA | W55: VALOR TOTAL A PAGAR | AA55: SALDO POR PAGAR
E56: DESDE | H56: HASTA
C57: 1 | E57: 42552 | H57: 42582 | K57: =pabril!K57*4 -> 0.44 | N57: =pabril!W57+pmayo!W57+junio!W57 -> 366277635 | Q57: 120169825 | T57: 1922720 | W57: =+Q57+T57 -> 122092545 | AA57: =F33-N57-W57 -> 610462727
C60: SE CANCELA FACTURA DE VENTA 305 DE 2016
B64: CERTIFICACIÓN
B66: El / la suscrito (a) supervisor (a) / interventor (a) certifica:
B67: Que, | C67: =+I9 -> SEGURIDAD NÁPOLES | L67: , identificado(a) con | O67: =+I15 -> C.C. | Q67: Nº | R67: =+L15 -> 860523408-6 | W67: cumplió a satisfacción con el objeto del (la)
B68: =+I11 -> PRESTACIÓN DE SERVICIOS | M68: Nº | N68: =+I13 -> 89 | P68: de | Q68: =+O13 -> 2016 | S68: , de acuerdo con el informe presentado.
...

Sheet agosto
A3: MUNICIPIO DE QUIBDO
B4: CERTIFICADO DE SUPERVISIÓN
B7: INFORMACIÓN CONTRACTUAL
B9: Nombre del (la) Contratista | I9: SEGURIDAD NÁPOLES | S9: OBJETO | U9: LA PRESTACIÓN DEL SERVICIO DE VIGILANCIA Y SEGURIDAD PRIVADA CON ARMA PARA LAS 16 INSTITUCIONES EDUCATIVA (SEDE PREINCIPAL), 2 SEDES EDUCATIAS DEL MUNICIPIO DE QUIBDÓ, LA SEDE ADMINISTRATIVA DE LA SECRETARÍA DE EDUCACIÓN, LA ADMINISTRACIÓN CENTRAL Y LAS DIFERENTES SEDES Y ÁREAS DE LA ALCALDÍA MUNICPAL DE QUIBDÓ.
B11: Tipo de Contrato | I11: PRESTACIÓN DE SERVICIOS
B13: Contrato Nº | I13: 89 | K13: DE | O13: 2016
B15: Documento de Identidad | I15: C.C. | K15: Nº | L15: 860523408-6
B17: Nombre de Supervisor(a) o Interventor(a) | I17: DAICY MARIELA MOSQUERA - HAROLD RAMIREZ OROZCO
B19: Cargo Supervisor(a) o Interventor(a) | I19: SUPERVISORES
B21: INFORMACIÓN FINANCIERA
B23: Número cuenta del (a) Contratista | G23: 17391176580 | P23: Banco | R23: Bancolombia | Y23: Tipo cuenta | AA23: Corriente
B25: Fecha de inicio (Según Acta) | J25: 1 DE ABRIL DE 2016 | R25: Plazo de Ejecución | V25: 9 | X25: meses, y | AA25: días
T26: ,
B27: Fecha de terminación (Incluye prórrogas) | J27: 31 DE DICIEMBRE DE 2016
B29: APORTE ALCALDIA | F29: 1098832907 | M29: Prórrogas | Q29: Días
B30: ADICION 1 | F30: 0 | M30: Prórroga 1
B31: Adición 2 | M31: Prórroga 2
B32: Adición 3 | M32: Prórroga 3
B33: Valor total del contrato | F33: =+F29+F30 -> 1098832907
B35: INFORMACIÓN PRESUPUESTAL
T36: ,
D37: No. Certificado Disponibilidad Presupuestal | I37: No. Registro Presupuestal | M37: Fecha Registro Presupuestal | R37: Código Rubro Presupuestal | Y37: Valor a pagar por Rubro Presupuestal en el presente pago
D38: 42 | I38: 384 | M38: 42460 | R38: 1.1.2.2.2.1.3.2.1 | Y38: =abril!H2+abril!H3 -> 53335349 | AH38: =Y38*9 -> 4.8001814e+08 | AI38: 488264948
D39: 42 | I39: 384 | M39: 42460 | R39: 1.2.1.3.2.2.4.2.4 | Y39: =abril!H4+abril!H5 -> 61010135 | AH39: =Y39*9 -> 5.4909121e+08 | AI39: 548493111
D40: 42 | I40: 384 | M40: 42460 | R40: 1.2.1.3.2.3.2.2.06 | Y40: =abril!H6 -> 7747061.1 | AH40: =Y40*9 -> 69723550 | AI40: 62074812
AH41: =SUM(AH38:AH40) -> 1098832905 | AI41: =SUM(AI38:AI40) -> 1098832871
B44: INFORMACIÓN DE APORTES A SEGURIDAD SOCIAL
E46: Salud | G46: 1613400 | L46: EPS | O46: NUEVA EPS | T46: Número de planilla | X46: 8456881422
E48: Pension | G48: 6492100 | L48: Fondo Pensiones | O48: PORVENIR | T48: Número de planilla | X48: 8456881422
E50: A.R.P | G50: 1745300 | L50: A.R.P | O50: POSITIVA | T50: Número de planilla | X50: 8456881422
B51: ***Nota: El pago del Fondo de Solidaridad Pensional - FSP, aplica únicamente cuando la base de cotizacion es mayor a 4 SMMLV.
B53: INFORMACIÓN PARA LA LIQUIDACIÓN DEL PAGO
C55: No. PAGO | E55: PERÍODO DE PAGO | K55: PORCENTAJE DE EJECUCIÓN | N55: VALOR PAGADO | Q55: VALOR A PAGAR SIN IVA | T55: IVA | W55: VALOR TOTAL A PAGAR | AA55: SALDO POR PAGAR
E56: DESDE | H56: HASTA
C57: 1 | E57: 42583 | H57: 42613 | K57: =pabril!K57*5 -> 0.55 | N57: =pabril!W57+pmayo!W57+junio!W57+julio!W57 -> 488370180 | Q57: 120169825 | T57: 1922720 | W57: =+Q57+T57 -> 122092545 | AA57: =F33-N57-W57 -> 488370182
C60: SE CANCELA FACTURA DE VENTA 305 DE 2016
B64: CERTIFICACIÓN
B66: El / la suscrito (a) supervisor (a) / interventor (a) certifica:
B67: Que, | C67: =+I9 -> SEGURIDAD NÁPOLES | L67: , identificado(a) con | O67: =+I15 -> C.C. | Q67: Nº | R67: =+L15 -> 860523408-6 | W67: cumplió a satisfacción con el objeto del (la)
B68: =+I11 -> PRESTACIÓN DE SERVICIOS | M68: Nº | N68: =+I13 -> 89 | P68: de | Q68: =+O13 -> 2016 | S68: , de acuerdo con el informe presentado.
...

Sheet septiembre
A3: MUNICIPIO DE QUIBDO
B4: CERTIFICADO DE SUPERVISIÓN
B7: INFORMACIÓN CONTRACTUAL
B9: Nombre del (la) Contratista | I9: SEGURIDAD NÁPOLES | S9: OBJETO | U9: LA PRESTACIÓN DEL SERVICIO DE VIGILANCIA Y SEGURIDAD PRIVADA CON ARMA PARA LAS 16 INSTITUCIONES EDUCATIVA (SEDE PREINCIPAL), 2 SEDES EDUCATIAS DEL MUNICIPIO DE QUIBDÓ, LA SEDE ADMINISTRATIVA DE LA SECRETARÍA DE EDUCACIÓN, LA ADMINISTRACIÓN CENTRAL Y LAS DIFERENTES SEDES Y ÁREAS DE LA ALCALDÍA MUNICPAL DE QUIBDÓ.
B11: Tipo de Contrato | I11: PRESTACIÓN DE SERVICIOS
B13: Contrato Nº | I13: 89 | K13: DE | O13: 2016
B15: Documento de Identidad | I15: C.C. | K15: Nº | L15: 860523408-6
B17: Nombre de Supervisor(a) o Interventor(a) | I17: DAICY MARIELA MOSQUERA - HAROLD RAMIREZ OROZCO
B19: Cargo Supervisor(a) o Interventor(a) | I19: SUPERVISORES
B21: INFORMACIÓN FINANCIERA
B23: Número cuenta del (a) Contratista | G23: 17391176580 | P23: Banco | R23: Bancolombia | Y23: Tipo cuenta | AA23: Corriente
B25: Fecha de inicio (Según Acta) | J25: 1 DE ABRIL DE 2016 | R25: Plazo de Ejecución | V25: 9 | X25: meses, y | AA25: días
T26: ,
B27: Fecha de terminación (Incluye prórrogas) | J27: 31 DE DICIEMBRE DE 2016
B29: APORTE ALCALDIA | F29: 1098832907 | M29: Prórrogas | Q29: Días
B30: Adición 1 | F30: 0 | M30: Prórroga 1
B31: Adición 2 | M31: Prórroga 2
B32: Adición 3 | M32: Prórroga 3
B33: Valor total del contrato | F33: =+F29+F30 -> 1098832907
B35: INFORMACIÓN PRESUPUESTAL
T36: ,
D37: No. Certificado Disponibilidad Presupuestal | I37: No. Registro Presupuestal | M37: Fecha Registro Presupuestal | R37: Código Rubro Presupuestal | Y37: Valor a pagar por Rubro Presupuestal en el presente pago
D38: 42 | I38: 384 | M38: 42460 | R38: 1.1.2.2.2.1.3.2.1 | Y38: =abril!H2+abril!H3 -> 53335349 | AH38: =Y38*9 -> 4.8001814e+08 | AI38: 488264948
D39: 42 | I39: 384 | M39: 42460 | R39: 1.2.1.3.2.2.4.2.4 | Y39: =abril!H4+abril!H5 -> 61010135 | AH39: =Y39*9 -> 5.4909121e+08 | AI39: 548493111
D40: 42 | I40: 384 | M40: 42460 | R40: 1.2.1.3.2.3.2.2.06 | Y40: =abril!H6 -> 7747061.1 | AH40: =Y40*9 -> 69723550 | AI40: 62074812
AH41: =SUM(AH38:AH40) -> 1098832905 | AI41: =SUM(AI38:AI40) -> 1098832871
B44: INFORMACIÓN DE APORTES A SEGURIDAD SOCIAL
E46: Salud | G46: 1691400 | L46: EPS | O46: NUEVA EPS | T46: Número de planilla | X46: 8457826294
E48: Pension | G48: 6785640 | L48: Fondo Pensiones | O48: PORVENIR | T48: Número de planilla | X48: 8457826294
E50: A.R.P | G50: 1816600 | L50: A.R.P | O50: POSITIVA | T50: Número de planilla | X50: 8457826294
B51: ***Nota: El pago del Fondo de Solidaridad Pensional - FSP, aplica únicamente cuando la base de cotizacion es mayor a 4 SMMLV.
AK52: =W57*9 -> 1098832905
B53: INFORMACIÓN PARA LA LIQUIDACIÓN DEL PAGO | AK53: =F33-AK52 -> 2
C55: No. PAGO | E55: PERÍODO DE PAGO | K55: PORCENTAJE DE EJECUCIÓN | N55: VALOR PAGADO | Q55: VALOR A PAGAR SIN IVA | T55: IVA | W55: VALOR TOTAL A PAGAR | AA55: SALDO POR PAGAR
E56: DESDE | H56: HASTA
C57: 1 | E57: 42614 | H57: 42643 | K57: =pabril!K57*6 -> 0.66 | N57: =pabril!W57+pmayo!W57+junio!W57+julio!W57+agosto!W57 -> 610462725 | Q57: 120169825 | T57: 1922720 | W57: =+Q57+T57 -> 122092545 | AA57: =F33-N57-W57 -> 366277637
C60: SE CANCELA FACTURA DE VENTA 344 DE 2016
B64: CERTIFICACIÓN
B66: El / la suscrito (a) supervisor (a) / interventor (a) certifica:
B67: Que, | C67: =+I9 -> SEGURIDAD NÁPOLES | L67: , identificado(a) con | O67: =+I15 -> C.C. | Q67: Nº | R67: =+L15 -> 860523408-6 | W67: cumplió a satisfacción con el objeto del (la)
...

Sheet octubre
A3: MUNICIPIO DE QUIBDO
B4: CERTIFICADO DE SUPERVISIÓN
B7: INFORMACIÓN CONTRACTUAL
B9: Nombre del (la) Contratista | I9: SEGURIDAD NÁPOLES | S9: OBJETO | U9: LA PRESTACIÓN DEL SERVICIO DE VIGILANCIA Y SEGURIDAD PRIVADA CON ARMA PARA LAS 16 INSTITUCIONES EDUCATIVA (SEDE PREINCIPAL), 2 SEDES EDUCATIAS DEL MUNICIPIO DE QUIBDÓ, LA SEDE ADMINISTRATIVA DE LA SECRETARÍA DE EDUCACIÓN, LA ADMINISTRACIÓN CENTRAL Y LAS DIFERENTES SEDES Y ÁREAS DE LA ALCALDÍA MUNICPAL DE QUIBDÓ.
B11: Tipo de Contrato | I11: PRESTACIÓN DE SERVICIOS
B13: Contrato Nº | I13: 89 | K13: DE | O13: 2016
B15: Documento de Identidad | I15: C.C. | K15: Nº | L15: 860523408-6
B17: Nombre de Supervisor(a) o Interventor(a) | I17: DAICY MARIELA MOSQUERA - HAROLD RAMIREZ OROZCO
B19: Cargo Supervisor(a) o Interventor(a) | I19: SUPERVISORES
B21: INFORMACIÓN FINANCIERA
B23: Número cuenta del (a) Contratista | G23: 17391176580 | P23: Banco | R23: Bancolombia | Y23: Tipo cuenta | AA23: Corriente
B25: Fecha de inicio (Según Acta) | J25: 1 DE ABRIL DE 2016 | R25: Plazo de Ejecución | V25: 9 | X25: meses, y | AA25: días
T26: ,
B27: Fecha de terminación (Incluye prórrogas) | J27: 31 DE DICIEMBRE DE 2016
B29: APORTE ALCALDIA | F29: 1098832907 | M29: Prórrogas | Q29: Días
B30: Adición 1 | F30: 0 | M30: Prórroga 1
B31: Adición 2 | M31: Prórroga 2
B32: Adición 3 | M32: Prórroga 3
B33: Valor total del contrato | F33: =+F29+F30 -> 1098832907
B35: INFORMACIÓN PRESUPUESTAL
T36: ,
D37: No. Certificado Disponibilidad Presupuestal | I37: No. Registro Presupuestal | M37: Fecha Registro Presupuestal | R37: Código Rubro Presupuestal | Y37: Valor a pagar por Rubro Presupuestal en el presente pago
D38: 42 | I38: 384 | M38: 42460 | R38: 1.1.2.2.2.1.3.2.1 | Y38: =abril!H2+abril!H3 -> 53335349 | AH38: =Y38*9 -> 4.8001814e+08 | AI38: 488264948
D39: 42 | I39: 384 | M39: 42460 | R39: 1.2.1.3.2.2.4.2.4 | Y39: =abril!H4+abril!H5 -> 61010135 | AH39: =Y39*9 -> 5.4909121e+08 | AI39: 548493111
D40: 42 | I40: 384 | M40: 42460 | R40: 1.2.1.3.2.3.2.2.06 | Y40: =abril!H6 -> 7747061.1 | AH40: =Y40*9 -> 69723550 | AI40: 62074812
AH41: =SUM(AH38:AH40) -> 1098832905 | AI41: =SUM(AI38:AI40) -> 1098832871
B44: INFORMACIÓN DE APORTES A SEGURIDAD SOCIAL
AH45: =Y38*6 -> 3.2001209e+08
E46: Salud | G46: 1691400 | L46: EPS | O46: NUEVA EPS | T46: Número de planilla | X46: 8458691114 | AH46: =Y39*6 -> 3.6606081e+08
AH47: =Y40*6 -> 46482367
E48: Pension | G48: 6785640 | L48: Fondo Pensiones | O48: PORVENIR | T48: Número de planilla | X48: 8458691114
E50: A.R.P | G50: 1816600 | L50: A.R.P | O50: POSITIVA | T50: Número de planilla | X50: 8458691114
B51: ***Nota: El pago del Fondo de Solidaridad Pensional - FSP, aplica únicamente cuando la base de cotizacion es mayor a 4 SMMLV.
AK52: =W57*9 -> 1098832905
B53: INFORMACIÓN PARA LA LIQUIDACIÓN DEL PAGO | AK53: =F33-AK52 -> 2
C55: No. PAGO | E55: PERÍODO DE PAGO | K55: PORCENTAJE DE EJECUCIÓN | N55: VALOR PAGADO | Q55: VALOR A PAGAR SIN IVA | T55: IVA | W55: VALOR TOTAL A PAGAR | AA55: SALDO POR PAGAR
E56: DESDE | H56: HASTA
C57: 1 | E57: 42644 | H57: 42674 | K57: =pabril!K57*7 -> 0.77 | N57: =pabril!W57+pmayo!W57+junio!W57+julio!W57+agosto!W57+septiembre!W57 -> 732555270 | Q57: 120169825 | T57: 1922720 | W57: =+Q57+T57 -> 122092545 | AA57: =F33-N57-W57 -> 244185092
AI58: 1
AI59: 16
...

Sheet noviembre
A3: MUNICIPIO DE QUIBDO
B4: CERTIFICADO DE SUPERVISIÓN
B7: INFORMACIÓN CONTRACTUAL
B9: Nombre del (la) Contratista | I9: SEGURIDAD NÁPOLES | S9: OBJETO | U9: LA PRESTACIÓN DEL SERVICIO DE VIGILANCIA Y SEGURIDAD PRIVADA CON ARMA PARA LAS 16 INSTITUCIONES EDUCATIVA (SEDE PREINCIPAL), 2 SEDES EDUCATIAS DEL MUNICIPIO DE QUIBDÓ, LA SEDE ADMINISTRATIVA DE LA SECRETARÍA DE EDUCACIÓN, LA ADMINISTRACIÓN CENTRAL Y LAS DIFERENTES SEDES Y ÁREAS DE LA ALCALDÍA MUNICPAL DE QUIBDÓ.
B11: Tipo de Contrato | I11: PRESTACIÓN DE SERVICIOS
B13: Contrato Nº | I13: 89 | K13: DE | O13: 2016
B15: Documento de Identidad | I15: C.C. | K15: Nº | L15: 860523408-6
B17: Nombre de Supervisor(a) o Interventor(a) | I17: DAICY MARIELA MOSQUERA - HAROLD RAMIREZ OROZCO
B19: Cargo Supervisor(a) o Interventor(a) | I19: SUPERVISORES
B21: INFORMACIÓN FINANCIERA
B23: Número cuenta del (a) Contratista | G23: 17391176580 | P23: Banco | R23: Bancolombia | Y23: Tipo cuenta | AA23: Corriente
B25: Fecha de inicio (Según Acta) | J25: 1 DE ABRIL DE 2016 | R25: Plazo de Ejecución | V25: 9 | X25: meses, y | AA25: días
T26: ,
B27: Fecha de terminación (Incluye prórrogas) | J27: 31 DE DICIEMBRE DE 2016
B29: APORTE ALCALDIA | F29: 1098832907 | M29: Prórrogas | Q29: Días
B30: Adición 1 | F30: 0 | M30: Prórroga 1
B31: Adición 2 | M31: Prórroga 2
B32: Adición 3 | M32: Prórroga 3
B33: Valor total del contrato | F33: =+F29+F30 -> 1098832907
B35: INFORMACIÓN PRESUPUESTAL
T36: ,
D37: No. Certificado Disponibilidad Presupuestal | I37: No. Registro Presupuestal | M37: Fecha Registro Presupuestal | R37: Código Rubro Presupuestal | Y37: Valor a pagar por Rubro Presupuestal en el presente pago
D38: 42 | I38: 384 | M38: 42460 | R38: 1.1.2.2.2.1.3.2.1 | Y38: =abril!H2+abril!H3 -> 53335349 | AH38: =Y38*9 -> 4.8001814e+08 | AI38: 488264948
D39: 42 | I39: 384 | M39: 42460 | R39: 1.2.1.3.2.2.4.2.4 | Y39: =abril!H4+abril!H5 -> 61010135 | AH39: =Y39*9 -> 5.4909121e+08 | AI39: 548493111
D40: 42 | I40: 384 | M40: 42460 | R40: 1.2.1.3.2.3.2.2.06 | Y40: =abril!H6 -> 7747061.1 | AH40: =Y40*9 -> 69723550 | AI40: 62074812
AH41: =SUM(AH38:AH40) -> 1098832905 | AI41: =SUM(AI38:AI40) -> 1098832871
B44: INFORMACIÓN DE APORTES A SEGURIDAD SOCIAL
AH45: =Y38*8 -> 4.2668279e+08 | AI45: =AI38-AH45 -> 61582156
E46: Salud | G46: 1691400 | L46: EPS | O46: NUEVA EPS | T46: Número de planilla | X46: 8459694314 | AH46: =Y39*8 -> 4.8808108e+08 | AI46: =AI39-AH46 -> 60412032
AH47: =Y40*8 -> 61976489 | AI47: =AI40-AH47 -> 98322.899
E48: Pension | G48: 6785640 | L48: Fondo Pensiones | O48: PORVENIR | T48: Número de planilla | X48: 8459694314 | AI48: ,
E50: A.R.P | G50: 1816600 | L50: A.R.P | O50: POSITIVA | T50: Número de planilla | X50: 8459694314 | AI50: ,
B51: ***Nota: El pago del Fondo de Solidaridad Pensional - FSP, aplica únicamente cuando la base de cotizacion es mayor a 4 SMMLV.
AK52: =W57*9 -> 1098832905
B53: INFORMACIÓN PARA LA LIQUIDACIÓN DEL PAGO | AK53: =F33-AK52 -> 2
C55: No. PAGO | E55: PERÍODO DE PAGO | K55: PORCENTAJE DE EJECUCIÓN | N55: VALOR PAGADO | Q55: VALOR A PAGAR SIN IVA | T55: IVA | W55: VALOR TOTAL A PAGAR | AA55: SALDO POR PAGAR
E56: DESDE | H56: HASTA
C57: 1 | E57: 42675 | H57: 31/11/2016 | K57: =pabril!K57*7 -> 0.77 | N57: =pabril!W57+pmayo!W57+junio!W57+julio!W57+agosto!W57+septiembre!W57+octubre!W57 -> 854647815 | Q57: 120169825 | T57: 1922720 | W57: =+Q57+T57 -> 122092545 | AA57: =F33-N57-W57 -> 122092547
AI58: 1
AI59: 16
...

Sheet diciembre
A3: MUNICIPIO DE QUIBDO
B4: CERTIFICADO DE SUPERVISIÓN
B7: INFORMACIÓN CONTRACTUAL
B9: Nombre del (la) Contratista | I9: SEGURIDAD NÁPOLES | S9: OBJETO | U9: LA PRESTACIÓN DEL SERVICIO DE VIGILANCIA Y SEGURIDAD PRIVADA CON ARMA PARA LAS 16 INSTITUCIONES EDUCATIVA (SEDE PREINCIPAL), 2 SEDES EDUCATIAS DEL MUNICIPIO DE QUIBDÓ, LA SEDE ADMINISTRATIVA DE LA SECRETARÍA DE EDUCACIÓN, LA ADMINISTRACIÓN CENTRAL Y LAS DIFERENTES SEDES Y ÁREAS DE LA ALCALDÍA MUNICPAL DE QUIBDÓ.
B11: Tipo de Contrato | I11: PRESTACIÓN DE SERVICIOS
B13: Contrato Nº | I13: 89 | K13: DE | O13: 2016
B15: Documento de Identidad | I15: C.C. | K15: Nº | L15: 860523408-6
B17: Nombre de Supervisor(a) o Interventor(a) | I17: DAICY MARIELA MOSQUERA - HAROLD RAMIREZ OROZCO
B19: Cargo Supervisor(a) o Interventor(a) | I19: SUPERVISORES
B21: INFORMACIÓN FINANCIERA
AI22: 82500000
B23: Número cuenta del (a) Contratista | G23: 17391176580 | P23: Banco | R23: Bancolombia | Y23: Tipo cuenta | AA23: Corriente | AI23: 77500000
AI24: 16093554
B25: Fecha de inicio (Según Acta) | J25: 1 DE ABRIL DE 2016 | R25: Plazo de Ejecución | V25: 9 | X25: meses, y | AA25: días | AI25: 40000000
T26: , | AI26: 65000000
B27: Fecha de terminación (Incluye prórrogas) | J27: 31 DE DICIEMBRE DE 2016 | AI27: 37500000
AI28: 25844500
B29: APORTE ALCALDIA | F29: 1098832907 | M29: Prórrogas | Q29: Días | AI29: 63745500
B30: Adición 1 | F30: 0 | M30: Prórroga 1
B31: Adición 2 | M31: Prórroga 2 | AI31: 12500000
B32: Adición 3 | M32: Prórroga 3 | AI32: 35942000
B33: Valor total del contrato | F33: =+F29+F30 -> 1098832907 | AI33: =SUM(AI22:AI32) -> 456625554
B35: INFORMACIÓN PRESUPUESTAL
T36: ,
D37: No. Certificado Disponibilidad Presupuestal | I37: No. Registro Presupuestal | M37: Fecha Registro Presupuestal | R37: Código Rubro Presupuestal | Y37: Valor a pagar por Rubro Presupuestal en el presente pago | AK37: 587090000
D38: 42 | I38: 384 | M38: 42460 | R38: 1.1.2.2.2.1.3.2.1 | Y38: =AH59 -> 61582192 | AH38: =Y38*9 -> 554239728 | AI38: 488264984 | AK38: =AK37-1174180000 -> -587090000
D39: 42 | I39: 384 | M39: 42460 | R39: 1.2.1.3.2.2.4.2.4 | Y39: =AH60 -> 60412031 | AH39: =Y39*9 -> 543708279 | AI39: 548493111 | AK39: 456625554
D40: 42 | I40: 384 | M40: 42460 | R40: 1.2.1.3.2.3.2.2.06 | Y40: =AH61 -> 98322 | AH40: =Y40*9 -> 884898 | AI40: 62074812 | AK40: =AK37-AK39 -> 130464446
AH41: =SUM(AH38:AH40) -> 1098832905 | AI41: =SUM(AI38:AI40) -> 1098832907
B44: INFORMACIÓN DE APORTES A SEGURIDAD SOCIAL
AH45: =Y38*8 -> 492657536 | AI45: =AI38-AH45 -> -4392552
E46: Salud | G46: 1744900 | L46: EPS | O46: NUEVA EPS | T46: Número de planilla | X46: 8460583618 | AH46: =Y39*8 -> 483296248 | AI46: =AI39-AH46 -> 65196863
AH47: =Y40*8 -> 786576 | AI47: =AI40-AH47 -> 61288236
E48: Pension | G48: 6995900 | L48: Fondo Pensiones | O48: PORVENIR | T48: Número de planilla | X48: 8460583618 | AI48: ,
E50: A.R.P | G50: 1863300 | L50: A.R.P | O50: POSITIVA | T50: Número de planilla | X50: 8460583618 | AI50: ,
B51: ***Nota: El pago del Fondo de Solidaridad Pensional - FSP, aplica únicamente cuando la base de cotizacion es mayor a 4 SMMLV.
AK52: =W57*9 -> 1098832905
B53: INFORMACIÓN PARA LA LIQUIDACIÓN DEL PAGO | AK53: =F33-AK52 -> 2
C55: No. PAGO | E55: PERÍODO DE PAGO | K55: PORCENTAJE DE EJECUCIÓN | N55: VALOR PAGADO | Q55: VALOR A PAGAR SIN IVA | T55: IVA | W55: VALOR TOTAL A PAGAR | AA55: SALDO POR PAGAR
E56: DESDE | H56: HASTA
...

Sheet enero 2017
A3: MUNICIPIO DE QUIBDO
B4: CERTIFICADO DE SUPERVISIÓN
B7: INFORMACIÓN CONTRACTUAL
B9: Nombre del (la) Contratista | I9: SEGURIDAD NÁPOLES | S9: OBJETO | U9: LA PRESTACIÓN DEL SERVICIO DE VIGILANCIA Y SEGURIDAD PRIVADA CON ARMA PARA LAS 16 INSTITUCIONES EDUCATIVA (SEDE PREINCIPAL), 2 SEDES EDUCATIAS DEL MUNICIPIO DE QUIBDÓ, LA SEDE ADMINISTRATIVA DE LA SECRETARÍA DE EDUCACIÓN, LA ADMINISTRACIÓN CENTRAL Y LAS DIFERENTES SEDES Y ÁREAS DE LA ALCALDÍA MUNICPAL DE QUIBDÓ.
B11: Tipo de Contrato | I11: PRESTACIÓN DE SERVICIOS
B13: Contrato Nº | I13: 89 | K13: DE | O13: 2016
B15: Documento de Identidad | I15: C.C. | K15: Nº | L15: 860523408-6
B17: Nombre de Supervisor(a) o Interventor(a) | I17: DAICY MARIELA MOSQUERA - HAROLD RAMIREZ OROZCO
B19: Cargo Supervisor(a) o Interventor(a) | I19: SUPERVISORES
B21: INFORMACIÓN FINANCIERA
AJ22: 82500000
B23: Número cuenta del (a) Contratista | G23: 17391176580 | P23: Banco | R23: Bancolombia | Y23: Tipo cuenta | AA23: Corriente | AJ23: 77500000
AJ24: 16093554
B25: Fecha de inicio (Según Acta) | J25: 1 DE ABRIL DE 2016 | R25: Plazo de Ejecución | V25: 10 | X25: meses, y | Z25: 15 | AA25: días | AJ25: 40000000
T26: , | AJ26: 65000000
B27: Fecha de terminación (Incluye prórrogas) | J27: 15 DE FEBRERO DE 2017 | AJ27: 37500000
AJ28: 25844500
B29: APORTE ALCALDIA | F29: 1098832907 | M29: Prórrogas | Q29: Días | AJ29: 63745500
B30: Adición 1 | F30: 0 | M30: Prórroga 1
B31: Adición 2 | F31: 215005281 | M31: Prórroga 2 | AJ31: 12500000
B32: Adición 3 | M32: Prórroga 3 | AJ32: 35942000
B33: Valor total del contrato | F33: =SUM(F29:I32) -> 1313838188 | AJ33: =SUM(AJ22:AJ32) -> 456625554
B35: INFORMACIÓN PRESUPUESTAL
T36: ,
D37: No. Certificado Disponibilidad Presupuestal | I37: No. Registro Presupuestal | M37: Fecha Registro Presupuestal | R37: Código Rubro Presupuestal | Y37: Valor a pagar por Rubro Presupuestal en el presente pago | AL37: 587090000
D38: 1425 | I38: 1630 | M38: 42734 | R38: 1.1.1.2.6.2.05 | Y38: =23776195*AM66 -> 15850797 | AI38: =Y38*9 -> 1.4265717e+08 | AJ38: 488264984 | AL38: =AL37-1174180000 -> -587090000
D39: 1425 | I39: 1630 | M39: 42734 | R39: 1.1.2.2.2.1.3.2.1 | Y39: =40149228*AM66 -> 26766152 | AI39: =Y39*9 -> 2.4089537e+08 | AJ39: 548493111 | AL39: 456625554
D40: 1425 | I40: 1630 | M40: 42734 | R40: 1.2.1.3.2.2.4.2.4 | Y40: =137518445*AM66 -> 91678964 | AI40: =Y40*9 -> 8.2511068e+08 | AJ40: 62074812 | AL40: =AL37-AL39 -> 130464446
D41: 1425 | I41: 1630 | M41: 42734 | R41: 1.2.1.3.2.3.2.2.06 | Y41: =13561413*AM66 -> 9040942.1 | AI41: =SUM(AI38:AI40) -> 1.2086632e+09 | AJ41: =SUM(AJ38:AJ40) -> 1098832907
B44: INFORMACIÓN DE APORTES A SEGURIDAD SOCIAL
AI45: =Y38*8 -> 1.2680637e+08 | AJ45: =AJ38-AI45 -> 3.6145861e+08
E46: Salud | G46: 1900100 | L46: EPS | O46: NUEVA EPS | T46: Número de planilla | X46: 8461973409 | AI46: =Y39*8 -> 2.1412922e+08 | AJ46: =AJ39-AI46 -> 3.3436389e+08
AI47: =Y40*8 -> 7.3343171e+08 | AJ47: =AJ40-AI47 -> -6.713569e+08
E48: Pension | G48: 7595100 | L48: Fondo Pensiones | O48: PORVENIR | T48: Número de planilla | X48: 8461973409 | AJ48: ,
E50: A.R.P | G50: 1963900 | L50: A.R.P | O50: POSITIVA | T50: Número de planilla | X50: 8461973409 | AJ50: ,
B51: ***Nota: El pago del Fondo de Solidaridad Pensional - FSP, aplica únicamente cuando la base de cotizacion es mayor a 4 SMMLV.
AL52: =W57*9 -> 1290031695
B53: INFORMACIÓN PARA LA LIQUIDACIÓN DEL PAGO | AL53: =F33-AL52 -> 23806493
C55: No. PAGO | E55: PERÍODO DE PAGO | K55: PORCENTAJE DE EJECUCIÓN | N55: VALOR PAGADO | Q55: VALOR A PAGAR SIN IVA | T55: IVA | W55: VALOR TOTAL A PAGAR | AA55: SALDO POR PAGAR
E56: DESDE | H56: HASTA | AH56: =W57 -> 143336855
...
